<?xml version="1.0" ?>
<robot name="agv" xmlns:xacro="https://www.ros.org/wiki/xacro" >
    
  <material name="black">
    <color rgba="0.0 0.0 0.0 1.0"/>
  </material>
  <material name="blue">
    <color rgba="0.203125 0.23828125 0.28515625 1.0"/>
  </material>
  <material name="green">
    <color rgba="0.0 0.8 0.0 1.0"/>
  </material>
  <material name="grey">
    <color rgba="0.2 0.2 0.2 1.0"/>
  </material>
  <material name="orange">
    <color rgba="1.0 0.423529411765 0.0392156862745 1.0"/>
  </material>
  <material name="brown">
    <color rgba="0.870588235294 0.811764705882 0.764705882353 1.0"/>
  </material>
  <material name="red">
    <color rgba="0.80078125 0.12890625 0.1328125 1.0"/>
  </material>
  <material name="white">
    <color rgba="1.0 1.0 1.0 1.0"/>
  </material>  
  
  <gazebo reference="link_chassis">
    <material>Gazebo/Orange</material>
  </gazebo>
  <gazebo reference="link_left_wheel">
    <material>Gazebo/Blue</material>
  </gazebo>
  <gazebo reference="link_right_wheel">
    <material>Gazebo/Blue</material>
  </gazebo>
  
  
     <link name="base_link">
      <visual>
         <origin rpy="0 0 0" xyz="0 0 0" />
      </visual>
   </link>
  
  
  <link name="chassis">
    <!--pose>0 0 0.1 0 0 0</pose-->
    
    <inertial>
      <mass value="1"/>
      <origin rpy="0 0 0" xyz="0 0 0"/>
      <inertia ixx="0.000000001" ixy="0" ixz="0" iyy="0" iyz="0" izz="0"/>
    </inertial>
    
    <collision>
      <geometry>
        <box size="1.17 0.26 0.15"/>
      </geometry>
    </collision>
    
    <visual>
      <origin rpy="0 0 0" xyz="0 0 0"/>
      <geometry>
        <box size="1.17 0.26 0.15"/>
      </geometry>
      <material name="blue"/>
    </visual>
   
    </link>
    
    
  
  <!-- Create wheel right -->  
    
    <link name="wheel_1">
 
    
    <inertial>
      <mass value="0.5"/>
      <origin rpy="0 0 0" xyz="0 0 0"/>
      <inertia ixx="0.000000001" ixy="0" ixz="0" iyy="0" iyz="0" izz="0"/>
    </inertial>
    
    <collision>
    <origin rpy="0 1.57 0" xyz="0 0 0"/>
      <geometry>
        <cylinder length="0.1" radius="0.085"/>
      </geometry>
    </collision>
    
    <visual>
      <origin rpy="0 1.57 0" xyz="0 0 0"/>
      <geometry>
        <cylinder length="0.1" radius="0.085"/>
      </geometry>
      <material name="white"/>
    </visual>
   
    </link>
    
    
        <link name="wheel_1_dir">
     <inertial>
      <mass value="0.5"/>
      <origin rpy="0 0 0" xyz="0 0 0"/>
      <inertia ixx="0.000000001" ixy="0" ixz="0" iyy="0" iyz="0" izz="0"/>
    </inertial>
    
 
    </link>
    
    
        <link name="wheel_2">
 
    
    <inertial>
      <mass value="0.5"/>
      <origin rpy="0 0 0" xyz="0 0 0"/>
      <inertia ixx="0.000000001" ixy="0" ixz="0" iyy="0" iyz="0" izz="0"/>
    </inertial>
    
    <collision>
    <origin rpy="0 1.57 0" xyz="0 0 0"/>
      <geometry>
        <cylinder length="0.1" radius="0.085"/>
      </geometry>
    </collision>
    
    <visual>
      <origin rpy="0 1.57 0" xyz="0 0 0"/>
      <geometry>
        <cylinder length="0.1" radius="0.085"/>
      </geometry>
      <material name="white"/>
    </visual>
   
    </link>
    
    
        <link name="wheel_2_dir">
    <inertial>
      <mass value="0.5"/>
      <origin rpy="0 0 0" xyz="0 0 0"/>
      <inertia ixx="0.000000001" ixy="0" ixz="0" iyy="0" iyz="0" izz="0"/>
    </inertial>
    
    
    </link>
    
            <link name="wheel_3">
 
    
    <inertial>
      <mass value="0.5"/>
      <origin rpy="0 0 0" xyz="0 0 0"/>
      <inertia ixx="0.000000001" ixy="0" ixz="0" iyy="0" iyz="0" izz="0"/>
    </inertial>
    
    <collision>
    <origin rpy="0 1.57 0" xyz="0 0 0"/>
      <geometry>
        <cylinder length="0.1" radius="0.085"/>
      </geometry>
    </collision>
    
    <visual>
      <origin rpy="0 1.57 0" xyz="0 0 0"/>
      <geometry>
        <cylinder length="0.1" radius="0.085"/>
      </geometry>
      <material name="white"/>
    </visual>
   
    </link>
    
    
        <link name="wheel_3_dir">
    <inertial>
      <mass value="0.5"/>
      <origin rpy="0 0 0" xyz="0 0 0"/>
      <inertia ixx="0.000000001" ixy="0" ixz="0" iyy="0" iyz="0" izz="0"/>
    </inertial>
    
    
    </link>
    
                <link name="wheel_4">
 
    
    <inertial>
      <mass value="0.5"/>
      <origin rpy="0 0 0" xyz="0 0 0"/>
      <inertia ixx="0.000000001" ixy="0" ixz="0" iyy="0" iyz="0" izz="0"/>
    </inertial>
    
    <collision>
    <origin rpy="0 1.57 0" xyz="0 0 0"/>
      <geometry>
        <cylinder length="0.1" radius="0.085"/>
      </geometry>
    </collision>
    
    <visual>
      <origin rpy="0 1.57 0" xyz="0 0 0"/>
      <geometry>
        <cylinder length="0.1" radius="0.085"/>
      </geometry>
      <material name="white"/>
    </visual>
   
    </link>
    
    
        <link name="wheel_4_dir">
       <inertial>
      <mass value="0.5"/>
      <origin rpy="0 0 0" xyz="0 0 0"/>
      <inertia ixx="0.000000001" ixy="0" ixz="0" iyy="0" iyz="0" izz="0"/>
    </inertial>
    
    
    </link>
    
                <link name="wheel_5">
 
    
    <inertial>
      <mass value="0.5"/>
      <origin rpy="0 0 0" xyz="0 0 0"/>
      <inertia ixx="0.000000001" ixy="0" ixz="0" iyy="0" iyz="0" izz="0"/>
    </inertial>
    
    <collision>
    <origin rpy="0 1.57 0" xyz="0 0 0"/>
      <geometry>
        <cylinder length="0.1" radius="0.085"/>
      </geometry>
    </collision>
    
    <visual>
      <origin rpy="0 1.57 0" xyz="0 0 0"/>
      <geometry>
        <cylinder length="0.1" radius="0.085"/>
      </geometry>
      <material name="white"/>
    </visual>
   
    </link>
    
    
        <link name="wheel_5_dir">
   <inertial>
      <mass value="0.5"/>
      <origin rpy="0 0 0" xyz="0 0 0"/>
      <inertia ixx="0.000000001" ixy="0" ixz="0" iyy="0" iyz="0" izz="0"/>
    </inertial>
    
   
    </link>
    
    
                <link name="wheel_6">
 
    
    <inertial>
      <mass value="0.5"/>
      <origin rpy="0 0 0" xyz="0 0 0"/>
      <inertia ixx="0.000000001" ixy="0" ixz="0" iyy="0" iyz="0" izz="0"/>
    </inertial>
    
    <collision>
    <origin rpy="0 1.57 0" xyz="0 0 0"/>
      <geometry>
        <cylinder length="0.1" radius="0.085"/>
      </geometry>
    </collision>
    
    <visual>
      <origin rpy="0 1.57 0" xyz="0 0 0"/>
      <geometry>
        <cylinder length="0.1" radius="0.085"/>
      </geometry>
      <material name="white"/>
    </visual>
   
    </link>
    
    
        <link name="wheel_6_dir">
      <inertial>
      <mass value="0.5"/>
      <origin rpy="0 0 0" xyz="0 0 0"/>
      <inertia ixx="0.000000001" ixy="0" ixz="0" iyy="0" iyz="0" izz="0"/>
    </inertial>
    
   
    </link>
    
    
                <link name="wheel_7">
 
    
    <inertial>
      <mass value="0.5"/>
      <origin rpy="0 0 0" xyz="0 0 0"/>
      <inertia ixx="0.000000001" ixy="0" ixz="0" iyy="0" iyz="0" izz="0"/>
    </inertial>
    
    <collision>
    <origin rpy="0 1.57 0" xyz="0 0 0"/>
      <geometry>
        <cylinder length="0.1" radius="0.085"/>
      </geometry>
    </collision>
    
    <visual>
      <origin rpy="0 1.57 0" xyz="0 0 0"/>
      <geometry>
        <cylinder length="0.1" radius="0.085"/>
      </geometry>
      <material name="white"/>
    </visual>
   
    </link>
    
    
        <link name="wheel_7_dir">
     <inertial>
      <mass value="0.5"/>
      <origin rpy="0 0 0" xyz="0 0 0"/>
      <inertia ixx="0.000000001" ixy="0" ixz="0" iyy="0" iyz="0" izz="0"/>
    </inertial>
    
    
    </link>
    
                <link name="wheel_8">
 
    
     <inertial>
      <mass value="0.5"/>
      <origin rpy="0 0 0" xyz="0 0 0"/>
      <inertia ixx="0.000000001" ixy="0" ixz="0" iyy="0" iyz="0" izz="0"/>
    </inertial>
    
    <collision>
    <origin rpy="0 1.57 0" xyz="0 0 0"/>
      <geometry>
        <cylinder length="0.1" radius="0.085"/>
      </geometry>
    </collision>
    
    <visual>
      <origin rpy="0 1.57 0" xyz="0 0 0"/>
      <geometry>
        <cylinder length="0.1" radius="0.085"/>
      </geometry>
      <material name="white"/>
    </visual>
   
    </link>
    
    
        <link name="wheel_8_dir">
 
    <inertial>
      <mass value="0.5"/>
      <origin rpy="0 0 0" xyz="0 0 0"/>
      <inertia ixx="0.000000001" ixy="0" ixz="0" iyy="0" iyz="0" izz="0"/>
    </inertial>
    
    
    </link>
    
    
    
  <!--   Joint for right wheel  -->
  <joint name="joint_chassis" type="fixed">
    <origin rpy="0 0 0" xyz="0 0 0"/>
    <child link="chassis" />
    <parent link="base_link"/>
    <axis rpy="0 0 0" xyz="0 0 0"/>
    <!--limit effort="10000" velocity="1000"/>
    <joint_properties damping="1.0" friction="1.0" /-->
  </joint>  
  
    <joint name="joint_wheel_1_dir" type="fixed">
    <origin rpy="0 1.57 0" xyz="0.4 0.25 -0.05"/>
    <child link="wheel_1_dir" />
    <parent link="chassis"/>
   <limit effort="1000" velocity="1000" lower="-0.55" upper="0.55"/>
  
  </joint> 
  
    <joint name="joint_wheel_1" type="continuous">
    <origin rpy="0 0 1.57" xyz="0 0 0"/>
    <child link="wheel_1" />
    <parent link="wheel_1_dir"/>
   <limit effort="1000" velocity="1000"/>
   <joint_properties damping="1.0" friction="1.0" />
    
  </joint> 
  
  
      <joint name="joint_wheel_2_dir" type="fixed">
    <origin rpy="0 1.57 0" xyz="0.13 0.25 -0.05"/>
    <child link="wheel_2_dir" />
    <parent link="chassis"/>
   <limit effort="1000" velocity="1000" lower="-0.55" upper="0.55"/>
  
  </joint> 
  
    <joint name="joint_wheel_2" type="continuous">
    <origin rpy="0 0 1.57" xyz="0 0 0"/>
    <child link="wheel_2" />
    <parent link="wheel_2_dir"/>
   <limit effort="1000" velocity="1000"/>
    <joint_properties damping="1.0" friction="1.0" />
  </joint>
  
       <joint name="joint_wheel_3_dir" type="fixed">
    <origin rpy="0 1.57 0" xyz="-0.13 0.25 -0.05"/>
    <child link="wheel_3_dir" />
    <parent link="chassis"/>
   <limit effort="1000" velocity="1000" lower="-0.55" upper="0.55"/>
  
  </joint> 
  
    <joint name="joint_wheel_3" type="continuous">
    <origin rpy="0 0 1.57" xyz="0 0 0"/>
    <child link="wheel_3" />
    <parent link="wheel_3_dir"/>
   <limit effort="1000" velocity="1000"/>
    <joint_properties damping="1.0" friction="1.0" />
  </joint>
  
   <joint name="joint_wheel_4_dir" type="fixed">
    <origin rpy="0 1.57 0" xyz="-0.4 0.25 -0.05"/>
    <child link="wheel_4_dir" />
    <parent link="chassis"/>
   <limit effort="1000" velocity="1000" lower="-0.55" upper="0.55"/>
  
  </joint> 
  
    <joint name="joint_wheel_4" type="continuous">
    <origin rpy="0 0 1.57" xyz="0 0 0"/>
    <child link="wheel_4" />
    <parent link="wheel_4_dir"/>
   <limit effort="1000" velocity="1000"/>
    <joint_properties damping="1.0" friction="1.0" />
  </joint>
  
     <joint name="joint_wheel_5_dir" type="fixed">
    <origin rpy="0 1.57 0" xyz="0.4 -0.25 -0.05"/>
    <child link="wheel_5_dir" />
    <parent link="chassis"/>
   <limit effort="1000" velocity="1000" lower="-0.55" upper="0.55"/>
  
  </joint> 
  
    <joint name="joint_wheel_5" type="continuous">
    <origin rpy="0 0 1.57" xyz="0 0 0"/>
    <child link="wheel_5" />
    <parent link="wheel_5_dir"/>
   <limit effort="1000" velocity="1000"/>
    <joint_properties damping="1.0" friction="1.0" />
  </joint>
  
     <joint name="joint_wheel_6_dir" type="fixed">
    <origin rpy="0 1.57 0" xyz="0.13 -0.25 -0.05"/>
    <child link="wheel_6_dir" />
    <parent link="chassis"/>
   <limit effort="1000" velocity="1000" lower="-0.55" upper="0.55"/>
  
  </joint> 
  
    <joint name="joint_wheel_6" type="continuous">
    <origin rpy="0 0 1.57" xyz="0 0 0"/>
    <child link="wheel_6" />
    <parent link="wheel_6_dir"/>
   <limit effort="1000" velocity="1000"/>
    <joint_properties damping="1.0" friction="1.0" />
  </joint>
  
     <joint name="joint_wheel_7_dir" type="fixed">
    <origin rpy="0 1.57 0" xyz="-0.13 -0.25 -0.05"/>
    <child link="wheel_7_dir" />
    <parent link="chassis"/>
   <limit effort="1000" velocity="1000" lower="-0.55" upper="0.55"/>
  
  </joint> 
  
    <joint name="joint_wheel_7" type="continuous">
    <origin rpy="0 0 1.57" xyz="0 0 0"/>
    <child link="wheel_7" />
    <parent link="wheel_7_dir"/>
   <limit effort="1000" velocity="1000"/>
    <joint_properties damping="1.0" friction="1.0" />
  </joint>
  
     <joint name="joint_wheel_8_dir" type="fixed">
    <origin rpy="0 1.57 0" xyz="-0.4 -0.25 -0.05"/>
    <child link="wheel_8_dir" />
    <parent link="chassis"/>
   <limit effort="1000" velocity="1000" lower="-0.55" upper="0.55"/>
  
  </joint> 
  
    <joint name="joint_wheel_8" type="continuous">
    <origin rpy="0 0 1.57" xyz="0 0 0"/>
    <child link="wheel_8" />
    <parent link="wheel_8_dir"/>
   <limit effort="1000" velocity="1000"/>
    <joint_properties damping="1.0" friction="1.0" />
  </joint>
  
  
  <!--gazebo reference="hokuyo_link">
    <sensor type="ray" name="head_hokuyo_sensor">
      <pose>0 0 2 0 0 0</pose>
      <visualize>true</visualize>
      <update_rate>40</update_rate>
      <ray>
        <scan>
          <horizontal>
            <samples>1080</samples>
            <resolution>1</resolution>
            <min_angle>-2.3559777</min_angle>
            <max_angle>2.3559777</max_angle>
          </horizontal>
        </scan>
        <range>
          <min>0.10</min>
          <max>30.0</max>
          <resolution>0.01</resolution>
        </range>
        <noise>
          <type>gaussian</type>
          
          <mean>0.0</mean>
          <stddev>0.01</stddev>
        </noise>
      </ray>
      <plugin name="gazebo_ros_head_hokuyo_controller" filename="libgazebo_ros_laser.so">
        <topicName>/hokuyo_scan</topicName>
        <frameName>hokuyo_link</frameName>
      </plugin>
    </sensor>
</gazebo-->

    <transmission name="tran_joint_wheel_1">
      <type>transmission_interface/SimpleTransmission</type>
      <joint name="joint_wheel_1">
        <hardwareInterface>hardware_interface/EffortJointInterface</hardwareInterface>
      </joint>
      <actuator name="motor_joint_wheel_1">
        <hardwareInterface>hardware_interface/EffortJointInterface</hardwareInterface>
        <mechanicalReduction>1</mechanicalReduction>
      </actuator>
    </transmission>
    
    <transmission name="tran_joint_wheel_2">
      <type>transmission_interface/SimpleTransmission</type>
      <joint name="joint_wheel_2">
        <hardwareInterface>hardware_interface/EffortJointInterface</hardwareInterface>
      </joint>
      <actuator name="motor_joint_wheel_2">
        <hardwareInterface>hardware_interface/EffortJointInterface</hardwareInterface>
        <mechanicalReduction>1</mechanicalReduction>
      </actuator>
    </transmission>
    
    <transmission name="tran_joint_wheel_3">
      <type>transmission_interface/SimpleTransmission</type>
      <joint name="joint_wheel_3">
        <hardwareInterface>hardware_interface/EffortJointInterface</hardwareInterface>
      </joint>
      <actuator name="motor_joint_wheel_3">
        <hardwareInterface>hardware_interface/EffortJointInterface</hardwareInterface>
        <mechanicalReduction>1</mechanicalReduction>
      </actuator>
    </transmission>
    
    <transmission name="tran_joint_wheel_4">
      <type>transmission_interface/SimpleTransmission</type>
      <joint name="joint_wheel_4">
        <hardwareInterface>hardware_interface/EffortJointInterface</hardwareInterface>
      </joint>
      <actuator name="motor_joint_wheel_4">
        <hardwareInterface>hardware_interface/EffortJointInterface</hardwareInterface>
        <mechanicalReduction>1</mechanicalReduction>
      </actuator>
    </transmission>
    
    <transmission name="tran_joint_wheel_5">
      <type>transmission_interface/SimpleTransmission</type>
      <joint name="joint_wheel_5">
        <hardwareInterface>hardware_interface/EffortJointInterface</hardwareInterface>
      </joint>
      <actuator name="motor_joint_wheel_5">
        <hardwareInterface>hardware_interface/EffortJointInterface</hardwareInterface>
        <mechanicalReduction>1</mechanicalReduction>
      </actuator>
    </transmission>
    
    <transmission name="tran_joint_wheel_6">
      <type>transmission_interface/SimpleTransmission</type>
      <joint name="joint_wheel_6">
        <hardwareInterface>hardware_interface/EffortJointInterface</hardwareInterface>
      </joint>
      <actuator name="motor_joint_wheel_6">
        <hardwareInterface>hardware_interface/EffortJointInterface</hardwareInterface>
        <mechanicalReduction>1</mechanicalReduction>
      </actuator>
    </transmission>
    
    <transmission name="tran_joint_wheel_7">
      <type>transmission_interface/SimpleTransmission</type>
      <joint name="joint_wheel_7">
        <hardwareInterface>hardware_interface/EffortJointInterface</hardwareInterface>
      </joint>
      <actuator name="motor_joint_wheel_7">
        <hardwareInterface>hardware_interface/EffortJointInterface</hardwareInterface>
        <mechanicalReduction>1</mechanicalReduction>
      </actuator>
    </transmission>
    
    <transmission name="tran_joint_wheel_8">
      <type>transmission_interface/SimpleTransmission</type>
      <joint name="joint_wheel_8">
        <hardwareInterface>hardware_interface/EffortJointInterface</hardwareInterface>
      </joint>
      <actuator name="motor_joint_wheel_8">
        <hardwareInterface>hardware_interface/EffortJointInterface</hardwareInterface>
        <mechanicalReduction>1</mechanicalReduction>
      </actuator>
    </transmission>

<gazebo>
  <plugin name="gazebo_ros_control" filename="libgazebo_ros_control.so">
    <robotNamespace>/agv</robotNamespace>
  </plugin>
</gazebo>
  
    
  
</robot>
