<?xml version="1.0" ?>
<robot name="agv" xmlns:xacro="https://www.ros.org/wiki/xacro" >
    
  <material name="black">
    <color rgba="0.0 0.0 0.0 1.0"/>
  </material>
  <material name="blue">
    <color rgba="0.203125 0.23828125 0.28515625 1.0"/>
  </material>
  <material name="green">
    <color rgba="0.0 0.8 0.0 1.0"/>
  </material>
  <material name="grey">
    <color rgba="0.2 0.2 0.2 1.0"/>
  </material>
  <material name="orange">
    <color rgba="1.0 0.423529411765 0.0392156862745 1.0"/>
  </material>
  <material name="brown">
    <color rgba="0.870588235294 0.811764705882 0.764705882353 1.0"/>
  </material>
  <material name="red">
    <color rgba="0.80078125 0.12890625 0.1328125 1.0"/>
  </material>
  <material name="white">
    <color rgba="1.0 1.0 1.0 1.0"/>
  </material>  
  
  <gazebo reference="link_chassis">
    <material>Gazebo/Orange</material>
  </gazebo>
  <gazebo reference="link_left_wheel">
    <material>Gazebo/Blue</material>
  </gazebo>
  <gazebo reference="link_right_wheel">
    <material>Gazebo/Blue</material>
  </gazebo>
    
  <link name="link_chassis">
    <!-- pose and inertial -->
    <pose>0 0 0.1 0 0 0</pose>
    
    <inertial>
      <mass value="26"/>
      <origin rpy="0 0 0" xyz="0 0 0.1"/>
      <inertia ixx="0.0395416666667" ixy="0" ixz="0" iyy="0.106208333333" iyz="0" izz="0.106208333333"/>
    </inertial>
    
    <collision name="collision_chassis">
      <geometry>
        <box size="1.17 0.26 0.15"/>
      </geometry>
    </collision>
    
    <visual>
      <origin rpy="0 0 0" xyz="0 0 0"/>
      <geometry>
        <box size="1.17 0.26 0.15"/>
      </geometry>
      <material name="blue"/>
    </visual>
    
    <!-- caster front -->
   
    </link>
  
  <!-- Create wheel right -->  
    
  <link name="link_right_wheel">    
    <inertial>
      <mass value="0.2"/>
      <origin rpy="0 1.5707 1.5707" xyz="0 0 0"/>
      <inertia ixx="0.00052666666" ixy="0" ixz="0" iyy="0.00052666666" iyz="0" izz="0.001"/>
    </inertial>
    
    <collision name="link_right_wheel_collision">
      <origin rpy="0 1.5707 1.5707" xyz="0 0 0" />
      <geometry>
       <cylinder length="0.1" radius="0.085"/>
      </geometry>
    </collision>
    
    <visual name="link_right_wheel_visual">
      <origin rpy="0 1.5707 1.5707" xyz="0 0 0"/>
      <geometry>
       <cylinder length="0.1" radius="0.085"/>
      </geometry>      
    </visual>
    
  </link>
  
    <link name="right_steering">    
    <inertial>
      <mass value="0.01"/>
      <origin rpy="0 1.5707 1.5707" xyz="0 0 0"/>
      <inertia ixx="0.00052666666" ixy="0" ixz="0" iyy="0.00052666666" iyz="0" izz="0.001"/>
    </inertial>
       
  </link>
  
    <link name="link_left_wheel">    
    <inertial>
      <mass value="0.2"/>
      <origin rpy="0 1.5707 1.5707" xyz="0 0 0"/>
      <inertia ixx="0.00052666666" ixy="0" ixz="0" iyy="0.00052666666" iyz="0" izz="0.001"/>
    </inertial>
    
    <collision name="link_left_wheel_collision">
      <origin rpy="0 1.5707 1.5707" xyz="0 0 0" />
      <geometry>
        <cylinder length="0.1" radius="0.085"/>
      </geometry>
    </collision>
    
    <visual name="link_left_wheel_visual">
      <origin rpy="0 1.5707 1.5707" xyz="0 0 0"/>
      <geometry>
        <cylinder length="0.1" radius="0.085"/>
      </geometry>      
    </visual>
    
  </link>
  
      <link name="link_left_wheel_dir">    
    <inertial>
      <mass value="0.01"/>
      <origin rpy="0 1.5707 1.5707" xyz="0 0 0"/>
      <inertia ixx="0.00052666666" ixy="0" ixz="0" iyy="0.00052666666" iyz="0" izz="0.001"/>
    </inertial>
    
    
  </link>
    
    
    <link name="link_left_wheel_2">    
    <inertial>
      <mass value="0.2"/>
      <origin rpy="0 1.5707 1.5707" xyz="0 0 0"/>
      <inertia ixx="0.00052666666" ixy="0" ixz="0" iyy="0.00052666666" iyz="0" izz="0.001"/>
    </inertial>
    
    <collision name="link_left_wheel_collision_2">
      <origin rpy="0 1.5707 1.5707" xyz="0 0 0" />
      <geometry>
        <cylinder length="0.1" radius="0.085"/>
      </geometry>
    </collision>
    
    <visual name="link_left_wheel_visual_2">
      <origin rpy="0 1.5707 1.5707" xyz="0 0 0"/>
      <geometry>
       <cylinder length="0.1" radius="0.085"/>
      </geometry>      
    </visual>
    
  </link>
  
       <link name="link_left_wheel_2_dir">    
    <inertial>
      <mass value="0.01"/>
      <origin rpy="0 1.5707 1.5707" xyz="0 0 0"/>
      <inertia ixx="0.00052666666" ixy="0" ixz="0" iyy="0.00052666666" iyz="0" izz="0.001"/>
    </inertial>
    
    
  </link>
  
  
      <link name="link_right_wheel_2">    
    <inertial>
      <mass value="0.2"/>
      <origin rpy="0 1.5707 1.5707" xyz="0 0 0"/>
      <inertia ixx="0.00052666666" ixy="0" ixz="0" iyy="0.00052666666" iyz="0" izz="0.001"/>
    </inertial>
    
    <collision name="link_right_wheel_collision_2">
      <origin rpy="0 1.5707 1.5707" xyz="0 0 0" />
      <geometry>
       <cylinder length="0.1" radius="0.085"/>
      </geometry>
    </collision>
    
    <visual name="link_right_wheel_visual_2">
      <origin rpy="0 1.5707 1.5707" xyz="0 0 0"/>
      <geometry>
      <cylinder length="0.1" radius="0.085"/>
      </geometry>      
    </visual>
    
  </link>
  
         <link name="link_right_wheel_2_dir">    
    <inertial>
      <mass value="0.01"/>
      <origin rpy="0 1.5707 1.5707" xyz="0 0 0"/>
      <inertia ixx="0.00052666666" ixy="0" ixz="0" iyy="0.00052666666" iyz="0" izz="0.001"/>
    </inertial>
    
    
  </link>
  
          <link name="link_right_wheel_3">    
    <inertial>
      <mass value="0.2"/>
      <origin rpy="0 1.5707 1.5707" xyz="0 0 0"/>
      <inertia ixx="0.00052666666" ixy="0" ixz="0" iyy="0.00052666666" iyz="0" izz="0.001"/>
    </inertial>
    
    <collision name="link_right_wheel_collision_3">
      <origin rpy="0 1.5707 1.5707" xyz="0 0 0" />
      <geometry>
      <cylinder length="0.1" radius="0.085"/>
      </geometry>
    </collision>
    
    <visual name="link_right_wheel_visual_3">
      <origin rpy="0 1.5707 1.5707" xyz="0 0 0"/>
      <geometry>
        <cylinder length="0.1" radius="0.085"/>
      </geometry>      
    </visual>
    
  </link>
  
         <link name="link_right_wheel_3_dir">    
    <inertial>
      <mass value="0.01"/>
      <origin rpy="0 1.5707 1.5707" xyz="0 0 0"/>
      <inertia ixx="0.00052666666" ixy="0" ixz="0" iyy="0.00052666666" iyz="0" izz="0.001"/>
    </inertial>
    
    
  </link>
  
          <link name="link_left_wheel_3">    
    <inertial>
      <mass value="0.2"/>
      <origin rpy="0 1.5707 1.5707" xyz="0 0 0"/>
      <inertia ixx="0.00052666666" ixy="0" ixz="0" iyy="0.00052666666" iyz="0" izz="0.001"/>
    </inertial>
    
    <collision name="link_left_wheel_collision_3">
      <origin rpy="0 1.5707 1.5707" xyz="0 0 0" />
      <geometry>
      <cylinder length="0.1" radius="0.085"/>
      </geometry>
    </collision>
    
    <visual name="link_left_wheel_visual_3">
      <origin rpy="0 1.5707 1.5707" xyz="0 0 0"/>
      <geometry>
        <cylinder length="0.1" radius="0.085"/>
      </geometry>      
    </visual>
    
  </link>
  
         <link name="link_left_wheel_3_dir">    
    <inertial>
      <mass value="0.01"/>
      <origin rpy="0 1.5707 1.5707" xyz="0 0 0"/>
      <inertia ixx="0.00052666666" ixy="0" ixz="0" iyy="0.00052666666" iyz="0" izz="0.001"/>
    </inertial>
    
    
  </link>
  
           <link name="link_left_wheel_4">    
    <inertial>
      <mass value="0.2"/>
      <origin rpy="0 1.5707 1.5707" xyz="0 0 0"/>
      <inertia ixx="0.00052666666" ixy="0" ixz="0" iyy="0.00052666666" iyz="0" izz="0.001"/>
    </inertial>
    
    <collision name="link_left_wheel_collision_4">
      <origin rpy="0 1.5707 1.5707" xyz="0 0 0" />
      <geometry>
        <cylinder length="0.1" radius="0.085"/>
      </geometry>
    </collision>
    
    <visual name="link_left_wheel_visual_4">
      <origin rpy="0 1.5707 1.5707" xyz="0 0 0"/>
      <geometry>
        <cylinder length="0.1" radius="0.085"/>
      </geometry>      
    </visual>
    
  </link>
  
         <link name="link_right_wheel_4_dir">    
    <inertial>
      <mass value="0.01"/>
      <origin rpy="0 1.5707 1.5707" xyz="0 0 0"/>
      <inertia ixx="0.00052666666" ixy="0" ixz="0" iyy="0.00052666666" iyz="0" izz="0.001"/>
    </inertial>
    
    
  </link>
  
  
           <link name="link_right_wheel_4">    
    <inertial>
      <mass value="0.2"/>
      <origin rpy="0 1.5707 1.5707" xyz="0 0 0"/>
      <inertia ixx="0.00052666666" ixy="0" ixz="0" iyy="0.00052666666" iyz="0" izz="0.001"/>
    </inertial>
    
    <collision name="link_right_wheel_collision_4">
      <origin rpy="0 1.5707 1.5707" xyz="0 0 0" />
      <geometry>
        <cylinder length="0.1" radius="0.085"/>
      </geometry>
    </collision>
    
    <visual name="link_right_wheel_visual_4">
      <origin rpy="0 1.5707 1.5707" xyz="0 0 0"/>
      <geometry>
        <cylinder length="0.1" radius="0.085"/>
      </geometry>      
    </visual>
    
  </link>
  
         <link name="link_left_wheel_4_dir">    
    <inertial>
      <mass value="0.01"/>
      <origin rpy="0 1.5707 1.5707" xyz="0 0 0"/>
      <inertia ixx="0.00052666666" ixy="0" ixz="0" iyy="0.00052666666" iyz="0" izz="0.001"/>
    </inertial>
    
    
  </link>
  
  
  <joint name="hokuyo_joint" type="fixed">
    
    <origin xyz="0 0 0.1" rpy="0 0 0"/>
    <parent link="link_chassis"/>
    <child link="hokuyo_link"/>
</joint>


<link name="hokuyo_link">
    <collision>
      <origin xyz="0 0 0" rpy="0 0 0"/>
      <geometry>
    <box size="0.05 0.05 0.05"/>
      </geometry>
    </collision>
    <visual>
      <origin xyz="0 0 0" rpy="0 0 0"/> 
      <geometry>
        <box size="0.05 0.05 0.05"/>
      </geometry>
    </visual>
    <inertial>
      <mass value="0.00001" />
      <origin xyz="0 0 0" rpy="0 0 0"/>
      <inertia ixx="0.00000000000000001" ixy="0" ixz="0" iyy="0" iyz="0" izz="0" />
    </inertial>
  </link>
  
<gazebo reference="hokuyo_link">
    <sensor type="ray" name="head_hokuyo_sensor">
      <pose>0 0 2 0 0 0</pose>
      <visualize>true</visualize>
      <update_rate>40</update_rate>
      <ray>
        <scan>
          <horizontal>
            <samples>1080</samples>
            <resolution>1</resolution>
            <min_angle>-2.3559777</min_angle>
            <max_angle>2.3559777</max_angle>
          </horizontal>
        </scan>
        <range>
          <min>0.10</min>
          <max>30.0</max>
          <resolution>0.01</resolution>
        </range>
        <noise>
          <type>gaussian</type>
          
          <mean>0.0</mean>
          <stddev>0.01</stddev>
        </noise>
      </ray>
      <plugin name="gazebo_ros_head_hokuyo_controller" filename="libgazebo_ros_laser.so">
        <topicName>/hokuyo_scan</topicName>
        <frameName>hokuyo_link</frameName>
      </plugin>
    </sensor>
</gazebo>
    
    
  <joint name="right_steering_joint" type="revolute">
    <origin rpy="0 0 0" xyz="-0.4 0.25 -0.05"/>
    <child link="right_steering" />
    <parent link="link_chassis"/>
    <axis rpy="0 0 0" xyz="0 0 1"/>
    <limit effort="10000" velocity="1000" lower="-0.55" upper="0.55"/>
    <joint_properties damping="1.0" friction="1.0" />
  </joint> 
    
  <!--   Joint for right wheel  -->
  <joint name="joint_right_wheel" type="continuous">
    <origin rpy="0 0 0" xyz="0 0 0"/>
    <child link="link_right_wheel" />
    <parent link="right_steering"/>
    <limit effort="10000" velocity="1000"/>
    <axis rpy="0 0 0" xyz="0 1 0"/>
    <joint_properties damping="1.0" friction="1.0" />
  </joint>  
  
  <joint name="joint_left_wheel_dir" type="revolute">
    <origin rpy="0 0 0" xyz="-0.4 -0.25 -0.05"/>
    <child link="link_left_wheel_dir" />
    <parent link="link_chassis"/>
    <axis rpy="0 0 0" xyz="0 0 1"/>
    <limit effort="10000" velocity="1000" lower="-0.55" upper="0.55"/>
    <joint_properties damping="1.0" friction="1.0" />
  </joint>
    

  <joint name="joint_left_wheel" type="continuous">
    <origin rpy="0 0 0" xyz="0 0 0"/>
    <child link="link_left_wheel" />
    <parent link="link_left_wheel_dir"/>
    <axis rpy="0 0 0" xyz="0 1 0"/>
    <limit effort="10000" velocity="1000"/>
    <joint_properties damping="1.0" friction="1.0" />
  </joint>   
  
  
    <joint name="joint_right_wheel_2_dir" type="revolute">
    <origin rpy="0 0 0" xyz="-0.13 0.25 -0.05"/>
    <child link="link_right_wheel_2_dir" />
    <parent link="link_chassis"/>
    <axis rpy="0 0 0" xyz="0 0 1"/>
    <limit effort="10000" velocity="1000" lower="-0.55" upper="0.55"/>
    <joint_properties damping="1.0" friction="1.0" />
  </joint>
  
  
   <joint name="joint_right_wheel_2" type="continuous">
    <origin rpy="0 0 0" xyz="0 0 0"/>
    <child link="link_right_wheel_2" />
    <parent link="link_right_wheel_2_dir"/>
    <axis rpy="0 0 0" xyz="0 1 0"/>
    <limit effort="10000" velocity="1000"/>
    <joint_properties damping="1.0" friction="1.0" />
  </joint>
  
      <joint name="joint_left_wheel_2_dir" type="revolute">
    <origin rpy="0 0 0" xyz="-0.13 -0.25 -0.05"/>
    <child link="link_left_wheel_2_dir" />
    <parent link="link_chassis"/>
    <axis rpy="0 0 0" xyz="0 0 1"/>
    <limit effort="10000" velocity="1000" lower="-0.55" upper="0.55"/>
    <joint_properties damping="1.0" friction="1.0" />
  </joint>
  

  <joint name="joint_left_wheel_2" type="continuous">
    <origin rpy="0 0 0" xyz="0 0 0"/>
    <child link="link_left_wheel_2" />
    <parent link="link_left_wheel_2_dir"/>
    <axis rpy="0 0 0" xyz="0 1 0"/>
    <limit effort="10000" velocity="1000"/>
    <joint_properties damping="1.0" friction="1.0" />
  </joint> 
  
  
 
       <joint name="joint_right_wheel_3_dir" type="revolute">
    <origin rpy="0 0 0" xyz="0.14 0.25 -0.05"/>
    <child link="link_right_wheel_3_dir" />
    <parent link="link_chassis"/>
    <axis rpy="0 0 0" xyz="0 0 1"/>
    <limit effort="10000" velocity="1000" lower="-0.55" upper="0.55"/>
    <joint_properties damping="1.0" friction="1.0" />
  </joint>
  

    
  <!--   Joint for right wheel  -->
  <joint name="joint_right_wheel_3" type="continuous">
    <origin rpy="0 0 0" xyz="0 0 0"/>
    <child link="link_right_wheel_3" />
    <parent link="link_right_wheel_3_dir"/>
    <axis rpy="0 0 0" xyz="0 1 0"/>
    <limit effort="10000" velocity="1000"/>
    <joint_properties damping="1.0" friction="1.0" />
  </joint>
  

           <joint name="joint_left_wheel_3_dir" type="revolute">
    <origin rpy="0 0 0" xyz="0.14 -0.25 -0.05"/>
    <child link="link_left_wheel_3_dir" />
    <parent link="link_chassis"/>
    <axis rpy="0 0 0" xyz="0 0 1"/>
    <limit effort="10000" velocity="1000" lower="-0.55" upper="0.55"/>
    <joint_properties damping="1.0" friction="1.0" />
  </joint>
  
  <!--   Joint for right wheel  -->
  <joint name="joint_left_wheel_3" type="continuous">
    <origin rpy="0 0 0" xyz="0 0 0"/>
    <child link="link_left_wheel_3" />
    <parent link="link_left_wheel_3_dir"/>
    <axis rpy="0 0 0" xyz="0 1 0"/>
    <limit effort="10000" velocity="1000"/>
    <joint_properties damping="1.0" friction="1.0" />
  </joint>
  
            <joint name="joint_right_wheel_4_dir" type="revolute">
    <origin rpy="0 0 0" xyz="0.41 0.25 -0.05"/>
    <child link="link_right_wheel_4_dir" />
    <parent link="link_chassis"/>
    <axis rpy="0 0 0" xyz="0 0 1"/>
    <limit effort="10000" velocity="1000" lower="-0.55" upper="0.55"/>
    <joint_properties damping="1.0" friction="1.0" />
  </joint>

      <joint name="joint_right_wheel_4" type="continuous">
    <origin rpy="0 0 0" xyz="0 0 0"/>
    <child link="link_right_wheel_4" />
    <parent link="link_right_wheel_4_dir"/>
    <axis rpy="0 0 0" xyz="0 1 0"/>
    <limit effort="10000" velocity="1000"/>
    <joint_properties damping="1.0" friction="1.0" />
  </joint>
    
    <joint name="joint_left_wheel_4_dir" type="revolute">
    <origin rpy="0 0 0" xyz="0.41 -0.25 -0.05"/>
    <child link="link_left_wheel_4_dir" />
    <parent link="link_chassis"/>
    <axis rpy="0 0 0" xyz="0 0 1"/>
    <limit effort="10000" velocity="1000" lower="-0.55" upper="0.55"/>
    <joint_properties damping="1.0" friction="1.0" />
  </joint>
    
  <!--   Joint for right wheel  -->
  <joint name="joint_left_wheel_4" type="continuous">
    <origin rpy="0 0 0" xyz="0 0 0"/>
    <child link="link_left_wheel_4" />
    <parent link="link_left_wheel_4_dir"/>
    <axis rpy="0 0 0" xyz="0 1 0"/>
    <limit effort="10000" velocity="1000"/>
    <joint_properties damping="1.0" friction="1.0" />
  </joint>
  
<!--transmission name="tran_joint_right_wheel">
      <type>transmission_interface/SimpleTransmission</type>
      <joint name="joint_right_wheel">
        <hardwareInterface>hardware_interface/EffortJointInterface</hardwareInterface>
      </joint>
      <actuator name="motor_joint_right_wheel">
        <hardwareInterface>hardware_interface/EffortJointInterface</hardwareInterface>
        <mechanicalReduction>1</mechanicalReduction>
      </actuator>
    </transmission>
    
       <transmission name="tran_joint_left_wheel">
      <type>transmission_interface/SimpleTransmission</type>
      <joint name="joint_left_wheel">
        <hardwareInterface>hardware_interface/EffortJointInterface</hardwareInterface>
      </joint>
      <actuator name="motor_joint_left_wheel">
        <hardwareInterface>hardware_interface/EffortJointInterface</hardwareInterface>
        <mechanicalReduction>1</mechanicalReduction>
      </actuator>
    </transmission>
    

    
     <transmission name="tran_joint_right_wheel_2">
      <type>transmission_interface/SimpleTransmission</type>
      <joint name="joint_right_wheel_2">
        <hardwareInterface>hardware_interface/EffortJointInterface</hardwareInterface>
      </joint>
      <actuator name="motor_joint_right_wheel_2">
        <hardwareInterface>hardware_interface/EffortJointInterface</hardwareInterface>
        <mechanicalReduction>1</mechanicalReduction>
      </actuator>
    </transmission>
    
        <transmission name="tran_joint_left_wheel_2">
      <type>transmission_interface/SimpleTransmission</type>
      <joint name="joint_left_wheel_2">
        <hardwareInterface>hardware_interface/EffortJointInterface</hardwareInterface>
      </joint>
      <actuator name="motor_joint_left_wheel_2">
        <hardwareInterface>hardware_interface/EffortJointInterface</hardwareInterface>
        <mechanicalReduction>1</mechanicalReduction>
      </actuator>
    </transmission>
    
        
    <transmission name="tran_joint_left_wheel_3">
      <type>transmission_interface/SimpleTransmission</type>
      <joint name="joint_left_wheel_3">
        <hardwareInterface>hardware_interface/EffortJointInterface</hardwareInterface>
      </joint>
      <actuator name="motor_joint_left_wheel_3">
        <hardwareInterface>hardware_interface/EffortJointInterface</hardwareInterface>
        <mechanicalReduction>1</mechanicalReduction>
      </actuator>
    </transmission>
    
       <transmission name="tran_joint_right_wheel_3">
      <type>transmission_interface/SimpleTransmission</type>
      <joint name="joint_right_wheel_3">
        <hardwareInterface>hardware_interface/EffortJointInterface</hardwareInterface>
      </joint>
      <actuator name="motor_joint_right_wheel_3">
        <hardwareInterface>hardware_interface/EffortJointInterface</hardwareInterface>
        <mechanicalReduction>1</mechanicalReduction>
      </actuator>
    </transmission>
    
    <transmission name="tran_joint_right_wheel_4">
      <type>transmission_interface/SimpleTransmission</type>
      <joint name="joint_right_wheel_4">
        <hardwareInterface>hardware_interface/EffortJointInterface</hardwareInterface>
      </joint>
      <actuator name="motor_joint_right_wheel_4">
        <hardwareInterface>hardware_interface/EffortJointInterface</hardwareInterface>
        <mechanicalReduction>1</mechanicalReduction>
      </actuator>
    </transmission>
    
    <transmission name="tran_joint_left_wheel_4">
      <type>transmission_interface/SimpleTransmission</type>
      <joint name="joint_left_wheel_4">
        <hardwareInterface>hardware_interface/EffortJointInterface</hardwareInterface>
      </joint>
      <actuator name="motor_joint_left_wheel_4">
        <hardwareInterface>hardware_interface/EffortJointInterface</hardwareInterface>
        <mechanicalReduction>1</mechanicalReduction>
      </actuator>
    </transmission-->
    
        <transmission name="tran_right_steering_joint">
      <type>transmission_interface/SimpleTransmission</type>
      <joint name="right_steering_joint">
        <hardwareInterface>hardware_interface/EffortJointInterface</hardwareInterface>
      </joint>
      <actuator name="motor_right_steering_joint">
        <hardwareInterface>hardware_interface/EffortJointInterface</hardwareInterface>
        <mechanicalReduction>1</mechanicalReduction>
      </actuator>
    </transmission>
    
    <transmission name="tran_joint_left_wheel_dir">
      <type>transmission_interface/SimpleTransmission</type>
      <joint name="joint_left_wheel_dir">
        <hardwareInterface>hardware_interface/EffortJointInterface</hardwareInterface>
      </joint>
      <actuator name="motor_joint_left_wheel_dir">
        <hardwareInterface>hardware_interface/EffortJointInterface</hardwareInterface>
        <mechanicalReduction>1</mechanicalReduction>
      </actuator>
    </transmission>
    

    
    <transmission name="tran_joint_right_wheel_2_dir">
      <type>transmission_interface/SimpleTransmission</type>
      <joint name="joint_right_wheel_2_dir">
        <hardwareInterface>hardware_interface/EffortJointInterface</hardwareInterface>
      </joint>
      <actuator name="motor_joint_right_wheel_2_dir">
        <hardwareInterface>hardware_interface/EffortJointInterface</hardwareInterface>
        <mechanicalReduction>1</mechanicalReduction>
      </actuator>
    </transmission>
    

    
    <transmission name="tran_joint_left_wheel_2_dir">
      <type>transmission_interface/SimpleTransmission</type>
      <joint name="joint_left_wheel_2_dir">
        <hardwareInterface>hardware_interface/EffortJointInterface</hardwareInterface>
      </joint>
      <actuator name="motor_joint_left_wheel_2_dir">
        <hardwareInterface>hardware_interface/EffortJointInterface</hardwareInterface>
        <mechanicalReduction>1</mechanicalReduction>
      </actuator>
    </transmission>
    
    <transmission name="tran_joint_left_wheel_3_dir">
      <type>transmission_interface/SimpleTransmission</type>
      <joint name="joint_left_wheel_3_dir">
        <hardwareInterface>hardware_interface/EffortJointInterface</hardwareInterface>
      </joint>
      <actuator name="motor_joint_left_wheel_3_dir">
        <hardwareInterface>hardware_interface/EffortJointInterface</hardwareInterface>
        <mechanicalReduction>1</mechanicalReduction>
      </actuator>
    </transmission>
    
    <transmission name="tran_joint_left_wheel_4_dir">
      <type>transmission_interface/SimpleTransmission</type>
      <joint name="joint_left_wheel_4_dir">
        <hardwareInterface>hardware_interface/EffortJointInterface</hardwareInterface>
      </joint>
      <actuator name="motor_joint_left_wheel_4_dir">
        <hardwareInterface>hardware_interface/EffortJointInterface</hardwareInterface>
        <mechanicalReduction>1</mechanicalReduction>
      </actuator>
    </transmission>

    
    <transmission name="tran_joint_right_wheel_3_dir">
      <type>transmission_interface/SimpleTransmission</type>
      <joint name="joint_right_wheel_3_dir">
        <hardwareInterface>hardware_interface/EffortJointInterface</hardwareInterface>
      </joint>
      <actuator name="motor_joint_right_wheel_3_dir">
        <hardwareInterface>hardware_interface/EffortJointInterface</hardwareInterface>
        <mechanicalReduction>1</mechanicalReduction>
      </actuator>
    </transmission>
    
    <transmission name="tran_joint_right_wheel_4_dir">
      <type>transmission_interface/SimpleTransmission</type>
      <joint name="joint_right_wheel_4_dir">
        <hardwareInterface>hardware_interface/EffortJointInterface</hardwareInterface>
      </joint>
      <actuator name="motor_joint_right_wheel_4_dir">
        <hardwareInterface>hardware_interface/EffortJointInterface</hardwareInterface>
        <mechanicalReduction>1</mechanicalReduction>
      </actuator>
    </transmission>
    
 
    


  
  <gazebo>
  <plugin name="gazebo_ros_control" filename="libgazebo_ros_control.so">
    <robotNamespace>/agv</robotNamespace>
  </plugin>
</gazebo>
  

<!--gazebo>
    <plugin filename="libgazebo_ros_diff_drive.so" name="differential_drive_controller">
      <alwaysOn>true</alwaysOn>
      <updateRate>20</updateRate>
      <leftJoint>joint_left_wheel</leftJoint>
      <rightJoint>joint_right_wheel</rightJoint>
      <wheelSeparation>0.4</wheelSeparation>
      <wheelDiameter>0.2</wheelDiameter>
      <torque>0.1</torque>
      <commandTopic>cmd_vel</commandTopic>
      <odometryTopic>odom</odometryTopic>
      <odometryFrame>odom</odometryFrame>
      <robotBaseFrame>link_chassis</robotBaseFrame>
    </plugin>
  </gazebo-->
  

    <!--gazebo>
        <plugin name="agv_multi_controller" filename="libdiffdrive_plugin_multi_wheel.so">
        <commandTopic>cmd_vel</commandTopic>	
        <rightJoints>wheel_joint_front_right wheel_joint_center_right wheel_joint_back_right</rightJoints>
        <leftJoints>wheel_joint_front_left wheel_joint_center_left wheel_joint_back_left</leftJoints>
        <odometryTopic>world</odometryTopic>
        <odometryFrame>world</odometryFrame>
        <odometryRate>20.0</odometryRate>
	<publishOdometryTf>true</publishOdometryTf>
        <publishOdometryMsg>false</publishOdometryMsg>
        <robotBaseFrame>base_footprint</robotBaseFrame>
        </plugin>
    </gazebo-->
  
    
  
</robot>
