<?xml version="1.0" ?>
<robot name="agv" xmlns:xacro="https://www.ros.org/wiki/xacro" >


     <xacro:include filename="$(find robotnik_sensors)/urdf/all_sensors.urdf.xacro" />
        
        
  <material name="black">
    <color rgba="0.0 0.0 0.0 1.0"/>
  </material>
  <material name="blue">
    <color rgba="0.203125 0.23828125 0.28515625 1.0"/>
  </material>
  <material name="green">
    <color rgba="0.0 0.8 0.0 1.0"/>
  </material>
  <material name="grey">
    <color rgba="0.2 0.2 0.2 1.0"/>
  </material>
  <material name="orange">
    <color rgba="1.0 0.423529411765 0.0392156862745 1.0"/>
  </material>
  <material name="brown">
    <color rgba="0.870588235294 0.811764705882 0.764705882353 1.0"/>
  </material>
  <material name="red">
    <color rgba="0.80078125 0.12890625 0.1328125 1.0"/>
  </material>
  <material name="white">
    <color rgba="1.0 1.0 1.0 1.0"/>
  </material>  
  
  <gazebo reference="link_chassis">
    <material>Gazebo/Orange</material>
  </gazebo>
  <gazebo reference="link_left_wheel">
    <material>Gazebo/Blue</material>
  </gazebo>
  <gazebo reference="link_right_wheel">
    <material>Gazebo/Blue</material>
  </gazebo>
    

    
    
  <link name="link_chassis">
    <!-- pose and inertial -->
    <pose>0 0 0.1 0 0 0</pose>
    
    <inertial>
      <mass value="26"/>
      <origin rpy="0 0 0" xyz="0 0 0.1"/>
      <inertia ixx="0.0395416666667" ixy="0" ixz="0" iyy="0.106208333333" iyz="0" izz="0.106208333333"/>
    </inertial>
    
    <collision name="collision_chassis">
      <geometry>
        <box size="1.17 0.26 0.15"/>
      </geometry>
    </collision>
    
    <visual>
      <origin rpy="0 0 0" xyz="0 0 0"/>
      <geometry>
        <box size="1.17 0.26 0.15"/>
      </geometry>
      <material name="blue"/>
    </visual>
    
    <!-- caster front -->
   
    </link>
  
  <!-- Create wheel right -->  
    
  <link name="link_right_wheel">    
    <inertial>
      <mass value="0.2"/>
      <origin rpy="0 1.5707 1.5707" xyz="0 0 0"/>
      <inertia ixx="0.00052666666" ixy="0" ixz="0" iyy="0.00052666666" iyz="0" izz="0.001"/>
    </inertial>
    
    <collision name="link_right_wheel_collision">
      <origin rpy="0 1.5707 1.5707" xyz="0 0 0" />
      <geometry>
       <cylinder length="0.1" radius="0.085"/>
      </geometry>
    </collision>
    
    <visual name="link_right_wheel_visual">
      <origin rpy="0 1.5707 1.5707" xyz="0 0 0"/>
      <geometry>
       <cylinder length="0.1" radius="0.085"/>
      </geometry>      
    </visual>
    
  </link>
  
    <link name="link_left_wheel">    
    <inertial>
      <mass value="0.2"/>
      <origin rpy="0 1.5707 1.5707" xyz="0 0 0"/>
      <inertia ixx="0.00052666666" ixy="0" ixz="0" iyy="0.00052666666" iyz="0" izz="0.001"/>
    </inertial>
    
    <collision name="link_left_wheel_collision">
      <origin rpy="0 1.5707 1.5707" xyz="0 0 0" />
      <geometry>
        <cylinder length="0.1" radius="0.085"/>
      </geometry>
    </collision>
    
    <visual name="link_left_wheel_visual">
      <origin rpy="0 1.5707 1.5707" xyz="0 0 0"/>
      <geometry>
        <cylinder length="0.1" radius="0.085"/>
      </geometry>      
    </visual>
    
  </link>
    
    
    <link name="link_left_wheel_2">    
    <inertial>
      <mass value="0.2"/>
      <origin rpy="0 1.5707 1.5707" xyz="0 0 0"/>
      <inertia ixx="0.00052666666" ixy="0" ixz="0" iyy="0.00052666666" iyz="0" izz="0.001"/>
    </inertial>
    
    <collision name="link_left_wheel_collision_2">
      <origin rpy="0 1.5707 1.5707" xyz="0 0 0" />
      <geometry>
        <cylinder length="0.1" radius="0.085"/>
      </geometry>
    </collision>
    
    <visual name="link_left_wheel_visual_2">
      <origin rpy="0 1.5707 1.5707" xyz="0 0 0"/>
      <geometry>
       <cylinder length="0.1" radius="0.085"/>
      </geometry>      
    </visual>
    
  </link>
  
  
      <link name="link_right_wheel_2">    
    <inertial>
      <mass value="0.2"/>
      <origin rpy="0 1.5707 1.5707" xyz="0 0 0"/>
      <inertia ixx="0.00052666666" ixy="0" ixz="0" iyy="0.00052666666" iyz="0" izz="0.001"/>
    </inertial>
    
    <collision name="link_right_wheel_collision_2">
      <origin rpy="0 1.5707 1.5707" xyz="0 0 0" />
      <geometry>
       <cylinder length="0.1" radius="0.085"/>
      </geometry>
    </collision>
    
    <visual name="link_right_wheel_visual_2">
      <origin rpy="0 1.5707 1.5707" xyz="0 0 0"/>
      <geometry>
      <cylinder length="0.1" radius="0.085"/>
      </geometry>      
    </visual>
    
  </link>
  
          <link name="link_right_wheel_3">    
    <inertial>
      <mass value="0.2"/>
      <origin rpy="0 1.5707 1.5707" xyz="0 0 0"/>
      <inertia ixx="0.00052666666" ixy="0" ixz="0" iyy="0.00052666666" iyz="0" izz="0.001"/>
    </inertial>
    
    <collision name="link_right_wheel_collision_3">
      <origin rpy="0 1.5707 1.5707" xyz="0 0 0" />
      <geometry>
      <cylinder length="0.1" radius="0.085"/>
      </geometry>
    </collision>
    
    <visual name="link_right_wheel_visual_3">
      <origin rpy="0 1.5707 1.5707" xyz="0 0 0"/>
      <geometry>
        <cylinder length="0.1" radius="0.085"/>
      </geometry>      
    </visual>
    
  </link>
  
          <link name="link_left_wheel_3">    
    <inertial>
      <mass value="0.2"/>
      <origin rpy="0 1.5707 1.5707" xyz="0 0 0"/>
      <inertia ixx="0.00052666666" ixy="0" ixz="0" iyy="0.00052666666" iyz="0" izz="0.001"/>
    </inertial>
    
    <collision name="link_left_wheel_collision_3">
      <origin rpy="0 1.5707 1.5707" xyz="0 0 0" />
      <geometry>
      <cylinder length="0.1" radius="0.085"/>
      </geometry>
    </collision>
    
    <visual name="link_left_wheel_visual_3">
      <origin rpy="0 1.5707 1.5707" xyz="0 0 0"/>
      <geometry>
        <cylinder length="0.1" radius="0.085"/>
      </geometry>      
    </visual>
    
  </link>
  
           <link name="link_left_wheel_4">    
    <inertial>
      <mass value="0.2"/>
      <origin rpy="0 1.5707 1.5707" xyz="0 0 0"/>
      <inertia ixx="0.00052666666" ixy="0" ixz="0" iyy="0.00052666666" iyz="0" izz="0.001"/>
    </inertial>
    
    <collision name="link_left_wheel_collision_4">
      <origin rpy="0 1.5707 1.5707" xyz="0 0 0" />
      <geometry>
        <cylinder length="0.1" radius="0.085"/>
      </geometry>
    </collision>
    
    <visual name="link_left_wheel_visual_4">
      <origin rpy="0 1.5707 1.5707" xyz="0 0 0"/>
      <geometry>
        <cylinder length="0.1" radius="0.085"/>
      </geometry>      
    </visual>
    
  </link>
  
  
           <link name="link_right_wheel_4">    
    <inertial>
      <mass value="0.2"/>
      <origin rpy="0 1.5707 1.5707" xyz="0 0 0"/>
      <inertia ixx="0.00052666666" ixy="0" ixz="0" iyy="0.00052666666" iyz="0" izz="0.001"/>
    </inertial>
    
    <collision name="link_right_wheel_collision_4">
      <origin rpy="0 1.5707 1.5707" xyz="0 0 0" />
      <geometry>
        <cylinder length="0.1" radius="0.085"/>
      </geometry>
    </collision>
    
    <visual name="link_right_wheel_visual_4">
      <origin rpy="0 1.5707 1.5707" xyz="0 0 0"/>
      <geometry>
        <cylinder length="0.1" radius="0.085"/>
      </geometry>      
    </visual>
    
  </link>
    
  <!--   Joint for right wheel  -->
  <joint name="joint_right_wheel" type="continuous">
    <origin rpy="0 0 0" xyz="-0.4 0.15 -0.05"/>
    <child link="link_right_wheel" />
    <parent link="link_chassis"/>
    <axis rpy="0 0 0" xyz="0 1 0"/>
    <limit effort="10000" velocity="1000"/>
    <joint_properties damping="1.0" friction="1.0" />
  </joint>  
    

  <joint name="joint_left_wheel" type="continuous">
    <origin rpy="0 0 0" xyz="-0.4 -0.15 -0.05"/>
    <child link="link_left_wheel" />
    <parent link="link_chassis"/>
    <axis rpy="0 0 0" xyz="0 1 0"/>
    <limit effort="10000" velocity="1000"/>
    <joint_properties damping="1.0" friction="1.0" />
  </joint>   
  
   <joint name="joint_right_wheel_2" type="continuous">
    <origin rpy="0 0 0" xyz="-0.13 0.15 -0.05"/>
    <child link="link_right_wheel_2" />
    <parent link="link_chassis"/>
    <axis rpy="0 0 0" xyz="0 1 0"/>
    <limit effort="10000" velocity="1000"/>
    <joint_properties damping="1.0" friction="1.0" />
  </joint>
  

  <joint name="joint_left_wheel_2" type="continuous">
    <origin rpy="0 0 0" xyz="-0.13 -0.15 -0.05"/>
    <child link="link_left_wheel_2" />
    <parent link="link_chassis"/>
    <axis rpy="0 0 0" xyz="0 1 0"/>
    <limit effort="10000" velocity="1000"/>
    <joint_properties damping="1.0" friction="1.0" />
  </joint> 
  
  
 
 
  

    
  <!--   Joint for right wheel  -->
  <joint name="joint_right_wheel_3" type="continuous">
    <origin rpy="0 0 0" xyz="0.14 0.15 -0.05"/>
    <child link="link_right_wheel_3" />
    <parent link="link_chassis"/>
    <axis rpy="0 0 0" xyz="0 1 0"/>
    <limit effort="10000" velocity="1000"/>
    <joint_properties damping="1.0" friction="1.0" />
  </joint>
  

    
  <!--   Joint for right wheel  -->
  <joint name="joint_left_wheel_3" type="continuous">
    <origin rpy="0 0 0" xyz="0.14 -0.15 -0.05"/>
    <child link="link_left_wheel_3" />
    <parent link="link_chassis"/>
    <axis rpy="0 0 0" xyz="0 1 0"/>
    <limit effort="10000" velocity="1000"/>
    <joint_properties damping="1.0" friction="1.0" />
  </joint>
  

      <joint name="joint_right_wheel_4" type="continuous">
    <origin rpy="0 0 0" xyz="0.41 0.15 -0.05"/>
    <child link="link_right_wheel_4" />
    <parent link="link_chassis"/>
    <axis rpy="0 0 0" xyz="0 1 0"/>
    <limit effort="10000" velocity="1000"/>
    <joint_properties damping="1.0" friction="1.0" />
  </joint>
    
    
  <!--   Joint for right wheel  -->
  <joint name="joint_left_wheel_4" type="continuous">
    <origin rpy="0 0 0" xyz="0.41 -0.15 -0.05"/>
    <child link="link_left_wheel_4" />
    <parent link="link_chassis"/>
    <axis rpy="0 0 0" xyz="0 1 0"/>
    <limit effort="10000" velocity="1000"/>
    <joint_properties damping="1.0" friction="1.0" />
  </joint>
  
    

     
    <joint name="front_laser_joint" type="fixed">
      <origin xyz="0 0.0 0.14" rpy="0 0.0 0"/>
      <parent link="link_chassis"/>
      <child link="front_laser_base_link"/>
	</joint>

  
	<link name="front_laser_base_link">
		<collision>
			<origin xyz="-0.093 0 -0.0625" rpy="0 0 0"/>
			<geometry>
	     		<mesh filename="package://robotnik_sensors/meshes/sick_s3000.dae"/>
			</geometry>
		</collision>

		<visual>
			<origin xyz="-0.093 0 -0.0625" rpy="0 0 0"/>
			<geometry>
	     		<mesh filename="package://robotnik_sensors/meshes/sick_s3000.dae"/>
			</geometry>
		</visual>

		<inertial>
			<mass value="1e-5" />
			<origin xyz="0 0 0" rpy="0 0 0"/>
			<inertia ixx="1e-6" ixy="0" ixz="0" iyy="1e-6" iyz="0" izz="1e-6" />
		</inertial>
	</link>
	

  
    
  
    <gazebo reference="front_laser_base_link">
			<sensor type="ray" name="front_laser_sensor">
				<pose>0 0 0 0 0 0</pose>
				<visualize>false</visualize>
				<update_rate>16.6</update_rate>
				<ray>
					<scan>
						<horizontal>
							<samples>761</samples>
							<resolution>1</resolution>
							<min_angle>-1.6580</min_angle>  
							<max_angle>1.6580</max_angle>
						</horizontal>
					</scan>
					<range>
						<min>0.10</min>
						<max>49.0</max>
						<resolution>0.01</resolution>
					</range>
					<noise>
						<type>gaussian</type>
						<mean>0.0</mean>
						<stddev>0.01</stddev>
					</noise>
				</ray>
				<plugin name="front_laser_controller" filename="libgazebo_ros_laser.so">
					<topicName>front_laser/scan</topicName>
					<frameName>/front_laser_base_link</frameName>
				</plugin>
			</sensor>
		</gazebo>
  

  <!--   Joint for right wheel  -->

  
      <gazebo>
        <plugin name="agv_multi_controller" filename="libdiffdrive_plugin_multi_wheel.so">
        <commandTopic>cmd_vel</commandTopic>	
        <rightJoints>joint_right_wheel joint_right_wheel_2 joint_right_wheel_3 joint_right_wheel_4</rightJoints>
        <leftJoints>joint_left_wheel joint_left_wheel_2 joint_left_wheel_3 joint_left_wheel_4</leftJoints>
        <odometryTopic>world</odometryTopic>
        <odometryFrame>world</odometryFrame>
        <odometryRate>20.0</odometryRate>
	<publishOdometryTf>true</publishOdometryTf>
        <publishOdometryMsg>false</publishOdometryMsg>
        <robotBaseFrame>link_chassis</robotBaseFrame>
        </plugin>
    </gazebo>

  <gazebo>
    <plugin name="gazebo_ros_control" filename="libgazebo_ros_control.so"/>
  </gazebo>
  
    
  
</robot>
